<mujoco model="yam_v0">
  <compiler angle="radian" meshdir="assets"/>

  <default>
    <default class="yam">
      <site group="5" size="0.005" rgba="0 1 0 1"/>
      <joint axis="0 0 1"/>
      <default class="visual">
        <geom type="mesh" contype="0" conaffinity="0" density="0" group="2" material="black"/>
      </default>
      <default class="collision">
        <geom group="3" type="capsule"/>
        <default class="sphere_collision">
          <geom size="0.0006 0 0" type="sphere" rgba="1 0 0 1" group="4"/>
        </default>
      </default>
      <default class="finger">
        <joint type="slide" axis="0 0 -1"/>
      </default>
    </default>
  </default>

  <asset>
    <material name="black" rgba="0.25 0.25 0.25 1"/>
    <material name="white" rgba="0.9 0.9 0.9 1"/>
    <material name="tip_left_mat" rgba="0.25 0.25 0.25 1"/>
    <material name="tip_right_mat" rgba="0.25 0.25 0.25 1"/>
    <material name="finger" rgba="0.25 0.25 0.25 1"/>

    <mesh file="model2.stl"/>
    <mesh file="model2__2.stl"/>
    <mesh file="model2__3.stl"/>
    <mesh file="model2__4.stl"/>
    <mesh file="model2__5.stl"/>
    <mesh file="model2__6.stl"/>
    <mesh file="model2__7.stl"/>
    <mesh file="model2__8.stl"/>
    <mesh file="model2__9.stl"/>
    <mesh file="model2__10.stl"/>
    <mesh file="model2__11.stl"/>
    <mesh file="model2__12.stl"/>
    <mesh file="model2__13.stl"/>
    <mesh file="model2__14.stl"/>
    <mesh file="model2__15.stl"/>
    <mesh file="model2__16.stl"/>
    <mesh file="model2__17.stl"/>

    <!-- Gripper visual meshes. -->
    <mesh file="gripper.stl"/>
    <mesh file="tip_left.stl"/>
    <mesh file="tip_right.stl"/>
    <!-- Gripper collision meshes decomposed with V-HACD. -->
    <mesh name="gripper_hull_0" file="gripper_hull_0.stl"/>
    <mesh name="gripper_hull_1" file="gripper_hull_1.stl"/>
    <mesh name="gripper_hull_2" file="gripper_hull_2.stl"/>
    <mesh name="gripper_hull_3" file="gripper_hull_3.stl"/>
    <mesh name="gripper_hull_4" file="gripper_hull_4.stl"/>
    <mesh name="gripper_hull_5" file="gripper_hull_5.stl"/>
    <mesh name="gripper_hull_6" file="gripper_hull_6.stl"/>
    <mesh name="gripper_hull_7" file="gripper_hull_7.stl"/>
    <mesh name="tip_left_hull_0" file="tip_left_hull_0.stl"/>
    <mesh name="tip_left_hull_1" file="tip_left_hull_1.stl"/>
    <mesh name="tip_left_hull_2" file="tip_left_hull_2.stl"/>
    <mesh name="tip_left_hull_3" file="tip_left_hull_3.stl"/>
    <mesh name="tip_left_hull_4" file="tip_left_hull_4.stl"/>
    <mesh name="tip_left_hull_5" file="tip_left_hull_5.stl"/>
    <mesh name="tip_left_hull_6" file="tip_left_hull_6.stl"/>
    <mesh name="tip_left_hull_7" file="tip_left_hull_7.stl"/>
    <mesh name="tip_right_hull_0" file="tip_right_hull_0.stl"/>
    <mesh name="tip_right_hull_1" file="tip_right_hull_1.stl"/>
    <mesh name="tip_right_hull_2" file="tip_right_hull_2.stl"/>
    <mesh name="tip_right_hull_3" file="tip_right_hull_3.stl"/>
    <mesh name="tip_right_hull_4" file="tip_right_hull_4.stl"/>
    <mesh name="tip_right_hull_5" file="tip_right_hull_5.stl"/>
    <mesh name="tip_right_hull_6" file="tip_right_hull_6.stl"/>
    <mesh name="tip_right_hull_7" file="tip_right_hull_7.stl"/>

    <mesh name="camera_d405" file="d405.stl" scale="0.001 0.001 0.001"/>
  </asset>

  <worldbody>
    <light name="spotlight" mode="targetbodycom" target="link_6" pos="0 0 1"/>
    <camera name="front_cam" pos="1.1 0 .5" xyaxes="0 1 0 -0.3 0 0.7"/>
    <body name="arm" childclass="yam">
      <geom class="visual" pos="0 0 -0.0006" quat="1 0 0 1" mesh="model2"/>
      <geom name="base_collision" class="collision" size="0.033 0.01" pos="0.0 0.0 0.026" quat="1 0 0 0"/>
      <body name="link_1" pos="0 0 0.0631" quat="1 0 0 1">
        <inertial pos="-0.00192861 -0.00795735 0.0208176" quat="0.297851 0.642634 0.360045 0.607185" mass="0.12415"
          diaginertia="0.000180751 0.000145532 5.89179e-05"/>
        <joint name="joint1" range="-2.61799 3.05433"/>
        <geom class="visual" pos="5.26159e-07 2.34355e-07 -0.0632" quat="1 0 0 0" mesh="model2__2"/>
        <body name="link_2" pos="2.5e-05 -0.02 0.0409" quat="1 1 1 1">
          <inertial pos="0.132008 2.10599e-06 0.000293073" quat="1 1 1 1" mass="1.24434"
            diaginertia="0.0121902 0.0121318 0.000683304"/>
          <joint name="joint2" range="0 3.66519"/>
          <geom class="visual" pos="0.0199992 -0.1041 -2.44738e-05" quat="1 -1 -1 -1" mesh="model2__3"/>
          <geom class="visual" pos="0.0199992 -0.1041 -2.44738e-05" quat="1 -1 -1 -1" mesh="model2__4"/>
          <geom class="visual" pos="0.0199992 -0.1041 -2.44738e-05" quat="1 -1 -1 -1" mesh="model2__5" material="white"/>
          <geom name="link2_1_collision" class="collision" size="0.032 0.11" pos="0.13 0 0" quat="1 0 1 0"/>
          <geom name="link2_2_collision" class="collision" size="0.033 0.02" pos="0 0.0 0" quat="1 0 0 0"/>
          <geom name="link2_3_collision" class="collision" size="0.033 0.025" pos="0.265 0 0" quat="1 0 0 0"/>
          <body name="link_3" pos="0.264 0 0" quat="0 1 0 0">
            <inertial pos="-0.121816 -0.054846 -0.000111108" quat="1 1 1 1" mass="0.853698"
              diaginertia="0.00699732 0.00696112 0.000788244"/>
            <joint name="joint3" range="0 3.66519"/>
            <geom class="visual" pos="-0.244001 0.104101 2.44738e-05" quat="1 1 1 -1" mesh="model2__6"/>
            <geom class="visual" pos="-0.244001 0.104101 2.44738e-05" quat="1 1 1 -1" mesh="model2__7"/>
            <geom class="visual" pos="-0.244001 0.104101 2.44738e-05" quat="1 1 1 -1" mesh="model2__8" material="white"/>
            <geom class="visual" pos="-0.244001 0.104101 2.44738e-05" quat="1 1 1 -1" mesh="model2__9"/>
            <geom name="link3_1_collision" class="collision" size="0.034 0.12" pos="-0.14 -0.06 0.0" quat="1 0 1 0"/>
            <geom name="link3_2_collision" class="collision" size="0.034 0.015" pos="-0.24 -0.06 0.0" quat="1 0 0 0"/>
            <body name="link_4" pos="-0.245 -0.06 0" quat="1 0 0 0">
              <inertial pos="-0.0769778 -0.0527104 0.000154878" quat="0.667 0.667 -0.236 -0.236" mass="0.463511"
                diaginertia="0.000791532 0.000744733 0.000282116"/>
              <joint name="joint4" range="-1.5708 1.5708"/>
              <geom class="visual" pos="0.00100023 0.164101 2.44738e-05" quat="1 1 1 -1" mesh="model2__10"/>
              <geom name="link4_1_collision" class="collision" size="0.03 0.015" pos="-0.073 -0.06 0.0" quat="1 1 0 0"/>
              <body name="link_5" pos="-0.074 -0.0395 2.5e-05" quat="1 -1 1 1">
                <inertial pos="3.64861e-05 0.00025665 0.0353526" quat="1 0 0 0" mass="0.350962"
                  diaginertia="0.000197802 0.0001775 0.000147402"/>
                <joint name="joint5" range="-1.5708 1.5708"/>
                <geom class="visual" pos="0 -0.0749971 0.203601" quat="1.32679e-06 1 0 0" mesh="model2__11"/>
                <geom name="link5_1_collision" class="collision" size="0.030 0.02" pos="0 0.025 0.0395" quat="1 1 0 0"/>
                <body name="link_6" pos="0 0.0353 0.0395" quat="0.5 0.5 -0.5 0.5">
                  <inertial pos="-3.57066e-05 0.000249371 -0.0293133" quat="0.667981 0.744113 -0.00433092 0.00882801"
                    mass="0.553219" diaginertia="0.000409686 0.000369758 0.000324415"/>
                  <joint name="joint6" axis="0 0 -1" range="-2.0944 2.0944"/>
                  <geom class="visual" mesh="gripper" pos="-0.014 -0.0463995 0.0731" quat="1 0 0 0"/>
                  <geom name="gripper_0_collision" class="collision" type="mesh" mesh="gripper_hull_0"
                    pos="-0.014 -0.0463995 0.0731" material="finger"/>
                  <geom name="gripper_7_collision" class="collision" type="mesh" mesh="gripper_hull_7"
                    pos="-0.014 -0.0463995 0.0731" material="finger"/>
                  <site name="tcp_site" quat="0 1 0 0" size="0.005" rgba="1 0 0 1"/>
                  <site name="grasp_site" pos="0 0 -0.1347" quat="0 1 0 0" size="0.005" rgba="0 1 0 1"/>
                  <body name="camera_d405" pos="-0.07207 0.00894 -0.07139" quat="0.14674 -0.69384 0.68857 -0.15143">
                    <geom class="visual" mesh="camera_d405"/>
                    <geom class="collision" type="box" size=".018 .018 .01" pos="0 0 -0.01" group="4"/>
                    <body name="camera_frame" pos="0.009 0 0" quat="0 0 0 1">
                      <camera name="camera_d405" pos="0 0 0" quat="0 1 0 0" resolution="1280 720" sensorsize="1.28 0.72"
                        focal="0.652725 0.651808" principal="-0.00806787 -0.00235107"/>
                    </body>
                  </body>
                  <body name="tip_left" pos="-0.0238981 0.0450619 -0.0545599" quat="0.499998 -0.5 -0.5 -0.500002">
                    <inertial pos="-0.0224716 0.0143408 -0.0426253" quat="0.498899 0.455348 -0.0576406 0.735143"
                      mass="0.0710042" diaginertia="6.24193e-05 6.01079e-05 2.83591e-05"/>
                    <joint name="left_finger" class="finger" range="0 0.0475"/>
                    <geom name="tip_left_visual" pos="0.129783 0.00999321 -0.0914614" quat="0.499998 0.5 0.500002 0.5"
                      mesh="tip_left" class="visual" material="finger"/>
                    <geom name="tip_l_0_collision" class="collision" type="mesh" mesh="tip_left_hull_0"
                      pos="0.129783 0.00999321 -0.0914614" quat="0.499998 0.5 0.500002 0.5" material="finger"/>
                    <geom name="tip_l_1_collision" class="collision" type="mesh" mesh="tip_left_hull_1"
                      pos="0.129783 0.00999321 -0.0914614" quat="0.499998 0.5 0.500002 0.5" material="finger"/>
                    <geom name="tip_l_3_collision" class="collision" type="mesh" mesh="tip_left_hull_3"
                      pos="0.129783 0.00999321 -0.0914614" quat="0.499998 0.5 0.500002 0.5" material="finger"/>
                    <geom name="tip_l_4_collision" class="collision" type="mesh" mesh="tip_left_hull_4"
                      pos="0.129783 0.00999321 -0.0914614" quat="0.499998 0.5 0.500002 0.5" material="finger"/>
                    <geom name="tip_l_7_collision" class="collision" type="mesh" mesh="tip_left_hull_7"
                      pos="0.129783 0.00999321 -0.0914614" quat="0.499998 0.5 0.500002 0.5" material="finger"/>
                  </body>
                  <body name="tip_right" pos="0.0238981 -0.0450619 -0.0545599" quat="1 1 0 0">
                    <inertial pos="-0.0143408 -0.0224716 -0.0426253" quat="0.281222 0.8726 0.16705 -0.362738"
                      mass="0.0710042" diaginertia="6.24193e-05 6.01079e-05 2.83591e-05"/>
                    <joint name="right_finger" class="finger" range="0 0.0475"/>
                    <geom name="tip_right_visual" pos="-0.0379932 0.129783 0.00133753" quat="1 -1 0 0" mesh="tip_right"
                      class="visual" material="finger"/>
                    <geom name="tip_r_1_collision" class="collision" type="mesh" mesh="tip_right_hull_1"
                      pos="-0.0379932 0.129783 0.00133753" quat="1 -1 0 0" material="finger"/>
                    <geom name="tip_r_2_collision" class="collision" type="mesh" mesh="tip_right_hull_2"
                      pos="-0.0379932 0.129783 0.00133753" quat="1 -1 0 0" material="finger"/>
                    <geom name="tip_r_3_collision" class="collision" type="mesh" mesh="tip_right_hull_3"
                      pos="-0.0379932 0.129783 0.00133753" quat="1 -1 0 0" material="finger"/>
                    <geom name="tip_r_4_collision" class="collision" type="mesh" mesh="tip_right_hull_4"
                      pos="-0.0379932 0.129783 0.00133753" quat="1 -1 0 0" material="finger"/>
                    <geom name="tip_r_7_collision" class="collision" type="mesh" mesh="tip_right_hull_7"
                      pos="-0.0379932 0.129783 0.00133753" quat="1 -1 0 0" material="finger"/>
                  </body>
                </body>
              </body>
            </body>
          </body>
        </body>
      </body>
    </body>
  </worldbody>

  <equality>
    <joint joint1="left_finger" joint2="right_finger" polycoef="0 1 0 0 0"/>
  </equality>
</mujoco>
